Workbook

Sheet Avance
A1: Avance de fichas y fotos para Mercado Libre
A2: Completo = ficha verificada en internet y al menos una foto. Texto azul: dato de entrada.
A4: Productos a publicar | B4: =COUNTA(Revisión!$A$2:$A$1150) -> 1149
A5: Con ficha verificada | B5: =COUNTIF(Revisión!$C$2:$C$1150,"Verificado") -> 1149
A6: Con al menos una foto | B6: =COUNTIF(Revisión!$N$2:$N$1150,">0") -> 1149
A7: Completos (ficha verificada y fotos) | B7: =COUNTIFS(Revisión!$C$2:$C$1150,"Verificado",Revisión!$N$2:$N$1150,">0") -> 1149
A8: Verificados sin fotos | B8: =B5-B7 -> 0
A9: Sin verificar (datos deducidos del nombre) | B9: =COUNTIF(Revisión!$C$2:$C$1150,"Sin verificar") -> 0
A10: Pendientes de investigar | B10: =COUNTIF(Revisión!$C$2:$C$1150,"Pendiente de investigar") -> 0
A11: Por investigar (sin verificar + pendientes) | B11: =B9+B10 -> 0
A12: Avance (completos / total) | B12: =IF(B4=0,0,B7/B4) -> 1
A13: Descartados de Mercado Libre (fuera del layout; hoja Descartados) | B13: =COUNTA(Descartados!$A$2:$A$5000) -> 14
A14: Productos por sesión | B14: 200 | C14: Límite de búsquedas web por sesión: 200 (1 búsqueda por producto)
A15: Sesiones realizadas | B15: 8
A16: Sesiones que faltan | B16: =ROUNDUP(B11/B14,0) -> 0
A17: Total de sesiones estimadas | B17: =B15+B16 -> 8
A19: Historial de sesiones
A20: Sesión | B20: Fecha | C20: Productos investigados | D20: Fichas verificadas | E20: Productos con fotos nuevas
A21: 1 | B21: 2026-09-29 | C21: 425 | D21: 122 | E21: 0
A22: 2 | B22: 2026-09-29 | C22: 199 | D22: 196 | E22: 315
A23: 3 | B23: 2026-09-29 | C23: 200 | D23: 194 | E23: 188
A24: 4 | B24: 2026-09-29 | C24: 200 | D24: 195 | E24: 190
A25: 5 | B25: 2026-09-29 | C25: 200 | D25: 191 | E25: 187
A26: 6 | B26: 2026-09-29 | C26: 200 | D26: 189 | E26: 181
A27: 7 | B27: 2026-09-29 | C27: 76 | D27: 68 | E27: 116
A28: 8 | B28: 2026-09-29 | C28: 0 | D28: 0 | E28: 11

Sheet Layout Mercado Libre
A1: SKU | B1: Código universal de producto | C1: Título | D1: Categoría (ID) | E1: Categoría (ruta) | F1: Precio [$] | G1: Cantidad | H1: Condición | I1: Tipo de publicación | J1: Descripción | K1: Forma de envío | L1: Costo de envío | M1: Retiro en persona | N1: Tipo de garantía | O1: ID de catálogo ML | P1: Marca | Q1: Fabricante / Laboratorio | R1: Línea | S1: Variante / Modelo | T1: Presentación | U1: Contenido neto | V1: Unidad de contenido | W1: Unidades por envase | X1: Principio activo | Y1: Concentración | Z1: Vía de administración | AA1: Edad / Etapa | AB1: Talla | AC1: Sabor / Aroma | AD1: Género | AE1: Tipo de piel / cabello | AF1: Registro sanitario | AG1: Otros atributos | AH1: Imagen 1 | AI1: Imagen 2 | AJ1: Imagen 3 | AK1: Imagen 4 | AL1: Imagen 5 | AM1: Imagen 6 | AN1: Línea de origen | AO1: Nombre en sistema | AP1: Estado de investigación
A2: 7501123013302 | B2: 7501123013302 | C2: Bedoyecta Tri Solución Inyectable 5 Jeringas 2 ml | D2: MLM457812 | E2: Salud y Equipamiento Médico > Cuidado de la Salud > Farmacia > Medicamentos de Venta Libre > Sistema Nervioso Venta Libre | F2: =Precios!R2 -> 419 | G2: 3099 | H2: =Parámetros!$B$28 -> Nuevo | I2: =Parámetros!$B$29 -> Clásica | J2: Descripción: Bedoyecta Tri es una solución inyectable de Laboratorios Grossman que combina tres vitaminas: hidroxocobalamina (vitamina B12), tiamina (vitamina B1) y piridoxina (vitamina B6). Se presenta en jeringas prellenadas de vidrio de 2 ml, listas para su aplicación intramuscular por personal de salud. Beneficios: - Aporta en una sola aplicación vitamina B12, B1 y B6. - Según su ficha, se utiliza en el tratamiento de deficiencias de vitaminas del complejo B. - Se emplea como apoyo en neuropatías nutricionales, diabéticas y alcohólicas, así como en ciática y otras neuropatías periféricas. - También se indica en anemia megaloblástica por deficiencia de vitamina B12. - Jeringa prellenada lista para usar. Composición: Cada jeringa de 2 ml contiene: - Hidroxocobalamina 10,000 mcg - Tiamina (clorhidrato) 100 mg - Piridoxina (clorhidrato) 50 mg Vehículo cbp 2 ml. Contiene alcohol bencílico como conservador. Modo de uso: Aplicación intramuscular profunda por personal de salud. La dosis media indicada en su ficha es de una a dos jeringas por semana según la gravedad del cuadro, o una aplicación cada 2 a 4 semanas en deficiencias crónicas de vitamina B12. La dosis y la duración del tratamiento deben ser determinadas por el médico. Presentación: Caja con 5 jeringas prellenadas de vidrio de 2 ml y 5 agujas desechables. Advertencias: No debe usarse en caso de hipersensibilidad a los componentes, policitemia vera, embarazo ni en recién nacidos. Puede causar erupción cutánea, náusea, vómito, neuropatía periférica y, en personas sensibles, reacciones alérgicas graves. Un exceso de vitamina B6 puede provocar neuropatía periférica; informe a su médico si consume otros multivitamínicos o suplementos. Conservar en lugar fresco. Lea las instrucciones del empaque. Consulte a su médico. No se deje al alcance de los niños. | K2: =Parámetros!$B$30 -> Mercado Envíos | L2: =IF(F2>=Parámetros!$B$7,"Envío gratis (obligatorio en Mercado Libre)",Parámetros!$B$31) -> Envío gratis (obligatorio en Mercado Libre) | M2: =Parámetros!$B$32 -> No acepto | N2: =Parámetros!$B$33 -> Sin garantía | O2: MLM40655899 | P2: Bedoyecta | Q2: Laboratorios Grossman | R2: Tri | S2: Solución inyectable 10,000 mcg/100 mg/50 mg | T2: Solución inyectable en jeringa prellenada | U2: 2 | V2: ml | W2: 5 | X2: Hidroxocobalamina, tiamina y piridoxina | Y2: 10,000 mcg/100 mg/50 mg por 2 ml | Z2: Intramuscular | AA2: Adultos | AF2: 84847 SSA IV | AG2: Incluye agujas desechables: 5; Formato de venta: Caja | AH2: https://raw.githubusercontent.com/zublimemx/marketplaces-product-images/main/products/7501123013302/images/7501123013302_1.jpg | AI2: https://raw.githubusercontent.com/zublimemx/marketplaces-product-images/main/products/7501123013302/images/7501123013302_2.jpg | AJ2: https://raw.githubusercontent.com/zublimemx/marketplaces-product-images/main/products/7501123013302/images/7501123013302_3.jpg | AN2: Farma | AO2: BEDOYECTA TRI AMP | AP2: Verificado
A3: 7501058623300 | B3: 7501058623300 | C3: Fórmula Infantil Nan Optipro 2 Lata 800 g | D3: MLM189058 | E3: Bebés > Comida para Bebés > Leche para Bebés | F3: =Precios!R3 -> 391 | G3: 1814 | H3: =Parámetros!$B$28 -> Nuevo | I3: =Parámetros!$B$29 -> Clásica | J3: Descripción: NAN Optipro 2 (presentada por Nestlé México como NAN 2 Optimal Pro) es una fórmula infantil en polvo para lactantes de 6 a 12 meses. Está elaborada con proteína de suero de leche OPTIPRO y enriquecida con HMO 2'FL, DHA, el probiótico Limosilactobacillus reuteri y hierro. Beneficios: - Contiene proteína de suero de leche desmineralizado OPTIPRO. - Incluye el oligosacárido de leche humana HMO 2'FL (2'-fucosilactosa) y DHA de aceite de pescado. - Contiene el probiótico Limosilactobacillus reuteri. - Fórmula adicionada con hierro, zinc, vitaminas A, C, D, E, K y del complejo B, y otros minerales. - Aporte por cada 100 kcal: 2 g de proteína, 4.8 g de grasa total y 12.2 g de carbohidratos. Ingredientes: Proteína de suero de leche de vaca desmineralizado OPTIPRO (26.84 %), lactosa, leche descremada, aceites vegetales (oleína de palma, palmiste, canola y maíz), citrato tricálcico, lecitina de soya, sales minerales, HMO (0.22 %) [2'-fucosilactosa], aceite de pescado (0.15 %) [DHA], cultivos probióticos de Limosilactobacillus reuteri (0.03 %), vitaminas y minerales. Contiene: leche, soya y aceite de pescado. Modo de uso: Indicada para lactantes de 6 a 12 meses. Prepárese siguiendo estrictamente las instrucciones de preparación y conservación de la etiqueta, con agua segura y utensilios limpios. Presentación: Lata con 800 g de fórmula en polvo. Advertencias: La leche materna es el mejor alimento para el bebé y debe continuarse el mayor tiempo posible. El uso de este producto debe hacerse bajo la orientación de un profesional de la salud. Contiene leche, soya y aceite de pescado. Una preparación o un almacenamiento incorrectos pueden ser perjudiciales para la salud del bebé. | K3: =Parámetros!$B$30 -> Mercado Envíos | L3: =IF(F3>=Parámetros!$B$7,"Envío gratis (obligatorio en Mercado Libre)",Parámetros!$B$31) -> Envío gratis (obligatorio en Mercado Libre) | M3: =Parámetros!$B$32 -> No acepto | N3: =Parámetros!$B$33 -> Sin garantía | P3: Nan | Q3: Nestlé | R3: Optipro | S3: Etapa 2 | T3: Lata en polvo | U3: 800 | V3: g | W3: 1 | AA3: 6 a 12 meses | AC3: Sin sabor | AD3: Unisex | AG3: Etapa: 2; Con HMO: Sí; Con DHA: Sí; Con probióticos: Sí; Con hierro: Sí; Formato de venta: Unidad; Nombre en empaque actual: Optimal Pro | AH3: https://raw.githubusercontent.com/zublimemx/marketplaces-product-images/main/products/7501058623300/images/7501058623300_1.jpg | AI3: https://raw.githubusercontent.com/zublimemx/marketplaces-product-images/main/products/7501058623300/images/7501058623300_2.jpg | AJ3: https://raw.githubusercontent.com/zublimemx/marketplaces-product-images/main/products/7501058623300/images/7501058623300_3.jpg | AN3: Farma + Mark | AO3: NAN 2 800GR | AP3: Verificado
A4: 7501058623317 | B4: 7501058623317 | C4: Fórmula Infantil Nan Optipro 1 Lata 800 g | D4: MLM189058 | E4: Bebés > Comida para Bebés > Leche para Bebés | F4: =Precios!R4 -> 406 | G4: 2350 | H4: =Parámetros!$B$28 -> Nuevo | I4: =Parámetros!$B$29 -> Clásica | J4: Descripción: NAN Optipro 1 (presentada por Nestlé México como NAN 1 Optimal Pro) es una fórmula infantil de inicio en polvo para bebés de 0 a 6 meses. Está elaborada con proteína de suero de leche OPTIPRO y enriquecida con HMO 2'FL, DHA y ARA, el probiótico Limosilactobacillus reuteri y hierro. Beneficios: - Contiene proteína OPTIPRO, DHA y ARA (ácidos grasos omega 3 y omega 6). - Incluye el oligosacárido de leche humana HMO 2'FL (2'-fucosilactosa). - Contiene el probiótico Limosilactobacillus reuteri. - Fórmula adicionada con hierro, vitaminas y minerales. - Aporte por cada 100 kcal: 1.85 g de proteína, 5.26 g de grasa total y 11.29 g de carbohidratos. Ingredientes: Proteína de suero de leche de vaca desmineralizado OPTIPRO (43.87 %), aceites vegetales (oleína de palma, palmiste, canola, maíz y girasol alto oleico), lactosa, minerales, vitaminas, cultivos probióticos de Limosilactobacillus reuteri, HMO (2'-fucosilactosa), DHA y ARA. Contiene: leche, soya y aceite de pescado. Modo de uso: Indicada para bebés de 0 a 6 meses. Prepárese siguiendo estrictamente las instrucciones de preparación y conservación de la etiqueta, con agua segura y utensilios limpios. Presentación: Lata con 800 g de fórmula en polvo. Advertencias: La leche materna es el mejor alimento para el bebé y debe continuarse el mayor tiempo posible. El uso de este producto debe hacerse bajo la orientación de un profesional de la salud. Contiene leche, soya y aceite de pescado. Una preparación o un almacenamiento incorrectos pueden ser perjudiciales para la salud del bebé. | K4: =Parámetros!$B$30 -> Mercado Envíos | L4: =IF(F4>=Parámetros!$B$7,"Envío gratis (obligatorio en Mercado Libre)",Parámetros!$B$31) -> Envío gratis (obligatorio en Mercado Libre) | M4: =Parámetros!$B$32 -> No acepto | N4: =Parámetros!$B$33 -> Sin garantía | O4: MLM28528415 | P4: Nan | Q4: Nestlé | R4: Optipro | S4: Etapa 1 | T4: Lata en polvo | U4: 800 | V4: g | W4: 1 | AA4: 0 a 6 meses | AC4: Sin sabor | AD4: Unisex | AG4: Etapa: 1; Con HMO: Sí; Con DHA: Sí; Con probióticos: Sí; Con hierro: Sí; Formato de venta: Unidad; Nombre en empaque actual: Optimal Pro | AH4: https://raw.githubusercontent.com/zublimemx/marketplaces-product-images/main/products/7501058623317/images/7501058623317_1.jpg | AI4: https://raw.githubusercontent.com/zublimemx/marketplaces-product-images/main/products/7501058623317/images/7501058623317_2.jpg | AJ4: https://raw.githubusercontent.com/zublimemx/marketplaces-product-images/main/products/7501058623317/images/7501058623317_3.jpg | AK4: https://raw.githubusercontent.com/zublimemx/marketplaces-product-images/main/products/7501058623317/images/7501058623317_4.jpg | AN4: Farma + Mark | AO4: NAN 1 800GR OPTIPRO | AP4: Verificado
A5: 7501318612655 | B5: 7501318612655 | C5: Aspirina Protect 100 mg 28 Tabletas | D5: MLM457820 | E5: Salud y Equipamiento Médico > Cuidado de la Salud > Farmacia > Medicamentos de Venta Libre > Para la Sangre Venta Libre | F5: =Precios!R5 -> 261 | G5: 12409 | H5: =Parámetros!$B$28 -> Nuevo | I5: =Parámetros!$B$29 -> Clásica | J5: Descripción: Aspirina Protect 100 mg es un medicamento de Bayer en tabletas de liberación retardada (gastrorresistentes), con 100 mg de ácido acetilsalicílico por tableta. Su cubierta está diseñada para resistir el ácido del estómago, por lo que la tableta se libera más adelante en el tubo digestivo. Beneficios: - Actúa sobre la agregación de las plaquetas y ayuda a prevenir la formación de coágulos de sangre. - Según su ficha, se utiliza para reducir el riesgo de mortalidad y morbilidad en el infarto agudo de miocardio y en la prevención secundaria de infarto y de evento vascular cerebral. - También se indica en ataque isquémico transitorio, angina de pecho e inestable y en la prevención de tromboembolia después de procedimientos vasculares. - Presentación de dosis baja (100 mg) para uso cardiovascular bajo indicación médica. Composición: Cada tableta contiene ácido acetilsalicílico 100 mg, con excipientes cbp. Modo de uso: Vía oral. Las tabletas gastrorresistentes se toman antes de los alimentos, con abundante líquido. La dosis y la duración del tratamiento dependen de la condición a tratar y deben ser indicadas por el médico. Presentación: Caja con 28 tabletas de liberación retardada de 100 mg. Advertencias: No debe usarse en caso de hipersensibilidad al ácido acetilsalicílico o a los salicilatos, asma inducida por salicilatos, úlcera gastroduodenal activa, trastornos hemorrágicos, insuficiencia renal, hepática o cardíaca graves, uso con metotrexato a dosis de 15 mg por semana o más, ni durante el tercer trimestre del embarazo. Puede aumentar el riesgo de sangrado y de lesiones gastrointestinales; tenga precaución si toma anticoagulantes. No se administre a niños o adolescentes con infecciones virales por el riesgo de síndrome de Reye. Lea las instrucciones del empaque. Consulte a su médico. No se deje al alcance de los niños. | K5: =Parámetros!$B$30 -> Mercado Envíos | L5: =IF(F5>=Parámetros!$B$7,"Envío gratis (obligatorio en Mercado Libre)",Parámetros!$B$31) -> A cargo del comprador | M5: =Parámetros!$B$32 -> No acepto | N5: =Parámetros!$B$33 -> Sin garantía | O5: MLM39473264 | P5: Aspirina | Q5: Bayer | R5: Protect | S5: 100 mg liberación retardada | T5: Tabletas de liberación retardada | U5: 28 | V5: tabletas | W5: 28 | X5: Ácido acetilsalicílico | Y5: 100 mg | Z5: Oral | AA5: Adultos | AG5: Formato de venta: Caja; Liberación: Retardada | AH5: https://raw.githubusercontent.com/zublimemx/marketplaces-product-images/main/products/7501318612655/images/7501318612655_2.jpg | AI5: https://raw.githubusercontent.com/zublimemx/marketplaces-product-images/main/products/7501318612655/images/7501318612655_4.jpg | AJ5: https://raw.githubusercontent.com/zublimemx/marketplaces-product-images/main/products/7501318612655/images/7501318612655_5.jpg | AN5: Farma | AO5: ASPIRINA PROTEC C 28 TABS 240 | AP5: Verificado
A6: 7501034692184 | B6: 7501034692184 | C6: Jardianz DPP 25 mg/5 mg 30 Tabletas | D6: MLM457821 | E6: Salud y Equipamiento Médico > Cuidado de la Salud > Farmacia > Medicamentos de Venta Libre > Digestivos Venta Libre | F6: =Precios!R6 -> 3069 | G6: 10 | H6: =Parámetros!$B$28 -> Nuevo | I6: =Parámetros!$B$29 -> Clásica | J6: Descripción: Jardianz DPP 25 mg/5 mg es un medicamento de Boehringer Ingelheim que combina en una sola tableta dos antidiabéticos orales: empagliflozina (inhibidor del cotransportador sodio-glucosa 2, SGLT2) y linagliptina (inhibidor de la enzima DPP-4). Beneficios: - Indicado en adultos con diabetes mellitus tipo 2 como complemento de la dieta y el ejercicio para el control de la glucosa en sangre. - Se utiliza cuando el control con metformina o sulfonilureas más uno de los componentes no es suficiente, o en pacientes que ya reciben ambos principios activos por separado. - Dos mecanismos de acción complementarios en una sola tableta. Composición: Cada tableta contiene empagliflozina 25 mg y linagliptina 5 mg. Modo de uso: Vía oral. La tableta se traga entera con agua, con o sin alimentos, aproximadamente a la misma hora cada día. La dosis y los ajustes (por ejemplo, según la función renal) deben ser determinados por el médico. Presentación: Caja con 30 tabletas. Advertencias: No debe usarse en diabetes tipo 1, enfermedad renal terminal o diálisis, ni en caso de hipersensibilidad a sus componentes. Existe riesgo de cetoacidosis diabética (suspender el tratamiento si se sospecha), infecciones urinarias y genitales y pancreatitis, y mayor riesgo de hipoglucemia si se usa con sulfonilureas o insulina. Se recomienda vigilar la función renal. Evite su uso durante el embarazo y la lactancia. No se recomienda en insuficiencia hepática grave. Lea las instrucciones del empaque. Consulte a su médico. No se deje al alcance de los niños. | K6: =Parámetros!$B$30 -> Mercado Envíos | L6: =IF(F6>=Parámetros!$B$7,"Envío gratis (obligatorio en Mercado Libre)",Parámetros!$B$31) -> Envío gratis (obligatorio en Mercado Libre) | M6: =Parámetros!$B$32 -> No acepto | N6: =Parámetros!$B$33 -> Sin garantía | O6: MLM40172306 | P6: Jardianz | Q6: Boehringer Ingelheim | R6: DPP | S6: 25 mg/5 mg | T6: Tabletas | U6: 30 | V6: tabletas | W6: 30 | X6: Empagliflozina y linagliptina | Y6: 25 mg/5 mg | Z6: Oral | AA6: Adultos | AF6: 512M2016 SSA IV | AG6: Formato de venta: Caja | AH6: https://raw.githubusercontent.com/zublimemx/marketplaces-product-images/main/products/7501034692184/images/7501034692184_1.jpg | AI6: https://raw.githubusercontent.com/zublimemx/marketplaces-product-images/main/products/7501034692184/images/7501034692184_2.jpg | AJ6: https://raw.githubusercontent.com/zublimemx/marketplaces-product-images/main/products/7501034692184/images/7501034692184_3.jpg | AN6: Farma | AO6: JARDIANZ DPP 25 5MG C30 | AP6: Verificado
A7: 7501943441804 | B7: 7501943441804 | C7: Pañales Huggies Supreme Unisex Etapa 5 36 Piezas | D7: MLM178488 | E7: Bebés > Higiene y Cuidado del Bebé > Pañales > Desechables | F7: =Precios!R7 -> 698 | G7: 281 | H7: =Parámetros!$B$28 -> Nuevo | I7: =Parámetros!$B$29 -> Clásica | J7: Descripción: Los pañales Huggies Supreme Etapa 5, de Kimberly-Clark, están diseñados para proteger la delicada piel del bebé con materiales de superior suavidad. Es la línea Huggies que se presenta como única clínica y dermatológicamente probada, con certificación Dermatest de cinco estrellas. Versión unisex para bebés de 11 a 14.5 kg. Características: - Clínica y dermatológicamente probados, con certificación Dermatest de 5 estrellas. - Materiales de superior suavidad que ayudan a evitar la irritación. - Manejo de la humedad que ayuda a mantener la piel fresca y sana. - Cintas ajustables para un ajuste cómodo y seguro que permite libertad de movimiento. - Diseños exclusivos en los pañales. - Unisex: para niños y niñas. Modo de uso: Abra el pañal y colóquelo debajo del bebé, lleve la parte delantera hacia arriba y sujete las cintas a la altura de la cintura, sin apretar en exceso. Cámbielo con frecuencia, en cuanto esté húmedo o sucio. Presentación: Paquete con 36 pañales desechables Etapa 5. Advertencias: Deseche el pañal usado en la basura, no en el inodoro. Mantenga el empaque plástico fuera del alcance de los niños. Verifique que la etapa corresponda al peso de su bebé. | K7: =Parámetros!$B$30 -> Mercado Envíos | L7: =IF(F7>=Parámetros!$B$7,"Envío gratis (obligatorio en Mercado Libre)",Parámetros!$B$31) -> Envío gratis (obligatorio en Mercado Libre) | M7: =Parámetros!$B$32 -> No acepto | N7: =Parámetros!$B$33 -> Sin garantía | O7: MLM17379809 | P7: Huggies | Q7: Kimberly-Clark de México | R7: Supreme | S7: Etapa 5 | T7: Pañales desechables | U7: 36 | V7: piezas | W7: 36 | AA7: Etapa 5 | AB7: Etapa 5 | AD7: Unisex | AG7: Peso del bebé: 11 a 14.5 kg; Dermatest 5 estrellas: Sí; Formato de venta: Paquete | AH7: https://raw.githubusercontent.com/zublimemx/marketplaces-product-images/main/products/7501943441804/images/7501943441804_1.jpg | AI7: https://raw.githubusercontent.com/zublimemx/marketplaces-product-images/main/products/7501943441804/images/7501943441804_3.jpg | AN7: Mark | AO7: HU SUP UNISEX E5 C/36 | AP7: Verificado
A8: 7501943445796 | B8: 7501943445796 | C8: Pañales Huggies Supreme Unisex Etapa 6 36 Piezas | D8: MLM178488 | E8: Bebés > Higiene y Cuidado del Bebé > Pañales > Desechables | F8: =Precios!R8 -> 529 | G8: 510 | H8: =Parámetros!$B$28 -> Nuevo | I8: =Parámetros!$B$29 -> Clásica | J8: Descripción: Los pañales Huggies Supreme Etapa 6, de Kimberly-Clark, están diseñados para proteger la delicada piel del bebé con materiales de superior suavidad. Es la línea Huggies que se presenta como única clínica y dermatológicamente probada, con certificación Dermatest de cinco estrellas. Versión unisex para bebés de más de 13.5 kg. Características: - Clínica y dermatológicamente probados, con certificación Dermatest de 5 estrellas. - Materiales de superior suavidad que ayudan a evitar la irritación. - Manejo de la humedad que ayuda a mantener la piel fresca y sana. - Cintas ajustables para un ajuste cómodo y seguro que permite libertad de movimiento. - Diseños exclusivos en los pañales. - Unisex: para niños y niñas. Modo de uso: Abra el pañal y colóquelo debajo del bebé, lleve la parte delantera hacia arriba y sujete las cintas a la altura de la cintura, sin apretar en exceso. Cámbielo con frecuencia, en cuanto esté húmedo o sucio. Presentación: Paquete con 36 pañales desechables Etapa 6. Advertencias: Deseche el pañal usado en la basura, no en el inodoro. Mantenga el empaque plástico fuera del alcance de los niños. Verifique que la etapa corresponda al peso de su bebé. | K8: =Parámetros!$B$30 -> Mercado Envíos | L8: =IF(F8>=Parámetros!$B$7,"Envío gratis (obligatorio en Mercado Libre)",Parámetros!$B$31) -> Envío gratis (obligatorio en Mercado Libre) | M8: =Parámetros!$B$32 -> No acepto | N8: =Parámetros!$B$33 -> Sin garantía | O8: MLM17379842 | P8: Huggies | Q8: Kimberly-Clark de México | R8: Supreme | S8: Etapa 6 | T8: Pañales desechables | U8: 36 | V8: piezas | W8: 36 | AA8: Etapa 6 | AB8: Etapa 6 | AD8: Unisex | AG8: Peso del bebé: más de 13.5 kg; Dermatest 5 estrellas: Sí; Formato de venta: Paquete | AH8: https://raw.githubusercontent.com/zublimemx/marketplaces-product-images/main/products/7501943445796/images/7501943445796_1.jpg | AI8: https://raw.githubusercontent.com/zublimemx/marketplaces-product-images/main/products/7501943445796/images/7501943445796_3.jpg | AN8: Mark | AO8: HU SUP UNISEX E6 C/36 | AP8: Verificado
A9: 7501058623188 | B9: 7501058623188 | C9: Fórmula Infantil Nan Optipro 1 Lata 400 g | D9: MLM189058 | E9: Bebés > Comida para Bebés > Leche para Bebés | F9: =Precios!R9 -> 212 | G9: 2092 | H9: =Parámetros!$B$28 -> Nuevo | I9: =Parámetros!$B$29 -> Clásica | J9: Descripción: NAN Optipro 1 (presentada por Nestlé México como NAN 1 Optimal Pro) es una fórmula infantil de inicio en polvo para bebés de 0 a 6 meses. Está elaborada con proteína de suero de leche OPTIPRO y enriquecida con HMO 2'FL, DHA y ARA, el probiótico Limosilactobacillus reuteri y hierro. Beneficios: - Contiene proteína OPTIPRO, DHA y ARA (ácidos grasos omega 3 y omega 6). - Incluye el oligosacárido de leche humana HMO 2'FL (2'-fucosilactosa). - Contiene el probiótico Limosilactobacillus reuteri. - Fórmula adicionada con hierro, vitaminas y minerales. - Aporte por cada 100 kcal: 1.85 g de proteína, 5.26 g de grasa total y 11.29 g de carbohidratos. Ingredientes: Proteína de suero de leche de vaca desmineralizado OPTIPRO (43.87 %), aceites vegetales (oleína de palma, palmiste, canola, maíz y girasol alto oleico), lactosa, minerales, vitaminas, cultivos probióticos de Limosilactobacillus reuteri, HMO (2'-fucosilactosa), DHA y ARA. Contiene: leche, soya y aceite de pescado. Modo de uso: Indicada para bebés de 0 a 6 meses. Prepárese siguiendo estrictamente las instrucciones de preparación y conservación de la etiqueta, con agua segura y utensilios limpios. Presentación: Lata con 400 g de fórmula en polvo. Advertencias: La leche materna es el mejor alimento para el bebé y debe continuarse el mayor tiempo posible. El uso de este producto debe hacerse bajo la orientación de un profesional de la salud. Contiene leche, soya y aceite de pescado. Una preparación o un almacenamiento incorrectos pueden ser perjudiciales para la salud del bebé. | K9: =Parámetros!$B$30 -> Mercado Envíos | L9: =IF(F9>=Parámetros!$B$7,"Envío gratis (obligatorio en Mercado Libre)",Parámetros!$B$31) -> A cargo del comprador | M9: =Parámetros!$B$32 -> No acepto | N9: =Parámetros!$B$33 -> Sin garantía | O9: MLM16139645 | P9: Nan | Q9: Nestlé | R9: Optipro | S9: Etapa 1 | T9: Lata en polvo | U9: 400 | V9: g | W9: 1 | AA9: 0 a 6 meses | AC9: Sin sabor | AD9: Unisex | AG9: Etapa: 1; Con HMO: Sí; Con DHA: Sí; Con probióticos: Sí; Con hierro: Sí; Formato de venta: Unidad; Nombre en empaque actual: Optimal Pro | AH9: https://raw.githubusercontent.com/zublimemx/marketplaces-product-images/main/products/7501058623188/images/7501058623188_1.jpg | AI9: https://raw.githubusercontent.com/zublimemx/marketplaces-product-images/main/products/7501058623188/images/7501058623188_2.jpg | AJ9: https://raw.githubusercontent.com/zublimemx/marketplaces-product-images/main/products/7501058623188/images/7501058623188_3.jpg | AN9: Farma + Mark | AO9: NAN 1 400 GR | AP9: Verificado
A10: 4015630064076 | B10: 4015630064076 | C10: Tiras Reactivas Accu-Chek Active 50 Piezas | D10: MLM189948 | E10: Salud y Equipamiento Médico > Equipamiento Médico > Equipos de Monitoreo > Medidores de Glucosa | F10: =Precios!R10 -> 354 | G10: 57 | H10: =Parámetros!$B$28 -> Nuevo | I10: =Parámetros!$B$29 -> Clásica | J10: Descripción: Tiras reactivas Accu-Chek Active, de Roche, para medir la concentración de glucosa en sangre capilar con el medidor Accu-Chek Active (el medidor no está incluido). Están diseñadas para obtener un resultado con una gota de sangre y sin necesidad de codificar. Características: - Requieren una gota de sangre de 1 a 2 µl. - El resultado se obtiene en aproximadamente 5 segundos cuando la sangre se aplica con la tira dentro del medidor (8 segundos si se aplica fuera). - Permiten agregar más sangre hasta 10 segundos después de la primera aplicación. - No requieren codificación: incluyen un chip negro permanente. - Determinación fotométrica de la glucosa. - Zona de dosificación con malla verde y bloques de color en la etiqueta para verificar visualmente la tira y el resultado. - Estables hasta la fecha indicada en el envase, incluso después de abierto. Modo de uso: 1. Inserte la tira en el medidor. 2. Puncione el dedo con un dispositivo de punción, por ejemplo Accu-Chek Softclix (no incluido). 3. Toque con cuidado la gota de sangre con el campo verde de la tira. 4. Lea el resultado en el medidor. Presentación: Envase con 50 tiras reactivas. Advertencias: Use las tiras únicamente con el medidor compatible. Mantenga el envase bien cerrado después de retirar cada tira para conservar su calidad. Consulte el manual del medidor y a su médico para interpretar los resultados. Mantenga fuera del alcance de los niños. | K10: =Parámetros!$B$30 -> Mercado Envíos | L10: =IF(F10>=Parámetros!$B$7,"Envío gratis (obligatorio en Mercado Libre)",Parámetros!$B$31) -> Envío gratis (obligatorio en Mercado Libre) | M10: =Parámetros!$B$32 -> No acepto | N10: =Parámetros!$B$33 -> Sin garantía | O10: MLM37784929 | P10: Accu-Chek | Q10: Roche | R10: Active | S10: Tiras reactivas de glucosa | T10: Tiras reactivas | U10: 50 | V10: tiras | W10: 50 | AA10: Adultos | AF10: 0679R2017 SSA | AG10: Compatible con: medidor Accu-Chek Active; Volumen de muestra: 1 a 2 µl; Tiempo de resultado: 5 segundos; Requiere codificación: No; Tecnología: Fotométrica; Formato de venta: Caja | AH10: https://raw.githubusercontent.com/zublimemx/marketplaces-product-images/main/products/4015630064076/images/4015630064076_1.jpg | AI10: https://raw.githubusercontent.com/zublimemx/marketplaces-product-images/main/products/4015630064076/images/4015630064076_2.jpg | AN10: Farma | AO10: ACCU CHEK C50 TIRAS ACTIVE | AP10: Verificado
A11: 8020030091252 | B11: 8020030091252 | C11: Vessel Due F 250 LRU 50 Cápsulas | D11: MLM457820 | E11: Salud y Equipamiento Médico > Cuidado de la Salud > Farmacia > Medicamentos de Venta Libre > Para la Sangre Venta Libre | F11: =Precios!R11 -> 829 | G11: 529 | H11: =Parámetros!$B$28 -> Nuevo | I11: =Parámetros!$B$29 -> Clásica | J11: Descripción: Vessel Due F 250 LRU es un medicamento de Alfasigma cuyo principio activo es la sulodexida, un antitrombótico de administración oral. Cada cápsula contiene 250 LRU (unidades lipasémicas) de sulodexida. Beneficios: - Según su ficha, está indicado en el tratamiento de la insuficiencia venosa crónica. - Se utiliza en el tratamiento de las úlceras venosas crónicas. - Se indica en la claudicación intermitente sintomática por enfermedad arterial oclusiva periférica (estadio II). Composición: Cada cápsula contiene sulodexida 250 LRU. Modo de uso: Vía oral. Las cápsulas deben ingerirse con líquido y separadas de las comidas. La dosis y la duración del tratamiento deben ser indicadas por el médico. Presentación: Caja con 50 cápsulas. Advertencias: No debe usarse en caso de hipersensibilidad a la sulodexida, a la heparina o a sustancias similares, ni en pacientes con enfermedad o diátesis hemorrágica. No se recomienda en menores de 18 años. Precaución si toma anticoagulantes orales, ya que puede aumentar su efecto. Evite su uso durante el embarazo y la lactancia. Lea las instrucciones del empaque. Consulte a su médico. No se deje al alcance de los niños. | K11: =Parámetros!$B$30 -> Mercado Envíos | L11: =IF(F11>=Parámetros!$B$7,"Envío gratis (obligatorio en Mercado Libre)",Parámetros!$B$31) -> Envío gratis (obligatorio en Mercado Libre) | M11: =Parámetros!$B$32 -> No acepto | N11: =Parámetros!$B$33 -> Sin garantía | O11: MLM39474253 | P11: Vessel | Q11: Alfasigma | R11: Due F | S11: 250 LRU | T11: Cápsulas | U11: 50 | V11: cápsulas | W11: 50 | X11: Sulodexida | Y11: 250 LRU | Z11: Oral | AA11: Adultos | AF11: 043M99 SSA IV | AG11: Formato de venta: Caja | AH11: https://raw.githubusercontent.com/zublimemx/marketplaces-product-images/main/products/8020030091252/images/8020030091252_4.jpg | AI11: https://raw.githubusercontent.com/zublimemx/marketplaces-product-images/main/products/8020030091252/images/8020030091252_2.jpg | AN11: Farma | AO11: VESSEL DUE F 250 CAPS50 | AP11: Verificado
A12: 7501943444966 | B12: 7501943444966 | C12: Pañales KleenBebé Suavelastic Etapa 5 Jumbo 40 Piezas | D12: MLM178488 | E12: Bebés > Higiene y Cuidado del Bebé > Pañales > Desechables | F12: =Precios!R12 -> 293 | G12: 417 | H12: =Parámetros!$B$28 -> Nuevo | I12: =Parámetros!$B$29 -> Clásica | J12: Descripción: Los pañales KleenBebé Suavelastic Max Etapa 5 (Jumbo), de Kimberly-Clark, están pensados para mantener seco al bebé por mucho más tiempo. Combinan tecnología Blockgel de alta absorción, ajuste con cuatro puntos de sujeción y una fórmula suave con ingredientes como manzanilla, aloe vera y vitamina E. Versión unisex para bebés de de 11 a 14.5 kg. Características: - Maxi sequedad: tecnología Blockgel y centro absorbente de alto desempeño para mantener seco al bebé por más tiempo. - Maxi ajuste: cuatro puntos de sujeción que ayudan a que el pañal no se caiga ni se deforme, con orejas elásticas ajustables y barreras laterales suaves. - Maxi cuidado: fórmula Vitta E Plus con vitamina E, aloe vera y manzanilla, y óxido de zinc que ayuda a prevenir la irritación. - Bolsillo trasero que ayuda a evitar fugas cuando el bebé está acostado. - Dermatológicamente certificados. Modo de uso: Abra el pañal y colóquelo debajo del bebé, lleve la parte delantera hacia arriba y sujete las cintas a la altura de la cintura, sin apretar en exceso. Cámbielo con frecuencia, en cuanto esté húmedo o sucio. Presentación: Paquete con 40 pañales desechables Etapa 5 (Jumbo). Advertencias: Deseche el pañal usado en la basura, no en el inodoro. Mantenga el empaque plástico fuera del alcance de los niños. Verifique que la etapa corresponda al peso de su bebé. | K12: =Parámetros!$B$30 -> Mercado Envíos | L12: =IF(F12>=Parámetros!$B$7,"Envío gratis (obligatorio en Mercado Libre)",Parámetros!$B$31) -> A cargo del comprador | M12: =Parámetros!$B$32 -> No acepto | N12: =Parámetros!$B$33 -> Sin garantía | O12: MLM18976117 | P12: KleenBebé | Q12: Kimberly-Clark de México | R12: Suavelastic | S12: Max Etapa 5 Jumbo | T12: Pañales desechables | U12: 40 | V12: piezas | W12: 40 | AA12: Etapa 5 | AB12: Jumbo | AD12: Unisex | AG12: Peso del bebé: 11 a 14.5 kg; Con óxido de zinc: Sí; Formato de venta: Paquete | AH12: https://raw.githubusercontent.com/zublimemx/marketplaces-product-images/main/products/7501943444966/images/7501943444966_4.jpg | AI12: https://raw.githubusercontent.com/zublimemx/marketplaces-product-images/main/products/7501943444966/images/7501943444966_5.jpg | AN12: Mark | AO12: SUAVE JUM E5 C/40 | AP12: Verificado
A13: 7501109902866 | B13: 7501109902866 | C13: Motrin Infantil Ibuprofeno 20 mg/ml Suspensión 120 ml | D13: MLM194673 | E13: Salud y Equipamiento Médico > Cuidado de la Salud > Farmacia > Medicamentos de Venta Libre > Analgésicos | F13: =Precios!R13 -> 399 | G13: 637 | H13: =Parámetros!$B$28 -> Nuevo | I13: =Parámetros!$B$29 -> Clásica | J13: Descripción: Motrin Infantil es una suspensión oral de ibuprofeno para niños de 2 a 12 años. Cada 100 ml contienen 2 g de ibuprofeno (20 mg por ml). Está libre de alcohol y tiene sabor a frutas. Beneficios: - Ayuda a reducir la fiebre en niños. - Alivia temporalmente el dolor leve a moderado asociado a resfriado, gripe, dolor de garganta, dolor de cabeza y dolor de muelas. - Según la marca, actúa en aproximadamente 15 minutos y sus efectos duran hasta 8 horas. - Incluye vasito dosificador y pipeta para medir la dosis. Composición: Ibuprofeno 2 g por cada 100 ml de suspensión (20 mg/ml), en vehículo cbp. Modo de uso: Vía oral. Agite bien antes de cada uso y utilice únicamente el dosificador incluido. Se administra una toma cada 6 a 8 horas, sin exceder 4 tomas en 24 horas. La dosis se determina de preferencia por el peso del niño: - 10 a 15 kg (2 a 3 años): 5 ml - 16 a 21 kg (4 a 5 años): 7.5 ml - 21.5 a 26.5 kg (6 a 8 años): 10 ml - 27 a 32 kg (9 a 10 años): 12.5 ml - 32.5 a 43 kg (11 a 12 años): 15 ml No lo use por más de 5 días sin consultar al médico. Presentación: Caja con un frasco de 120 ml, con vasito dosificador y pipeta. Conservar a temperatura ambiente controlada, entre 15 y 30 grados centígrados. Advertencias: No debe usarse en caso de hipersensibilidad al ibuprofeno, a la aspirina o a otros antiinflamatorios, úlcera péptica activa o hemorragia gastrointestinal, ni insuficiencia renal o hepática grave. Puede causar reacciones alérgicas graves y sangrado estomacal, sobre todo con uso prolongado o dosis mayores; los antiinflamatorios pueden aumentar el riesgo cardiovascular. Consulte al médico si el niño tiene úlceras, enfermedad renal o cardíaca, o toma anticoagulantes. Lea las instrucciones del empaque. Consulte a su médico. No se deje al alcance de los niños. | K13: =Parámetros!$B$30 -> Mercado Envíos | L13: =IF(F13>=Parámetros!$B$7,"Envío gratis (obligatorio en Mercado Libre)",Parámetros!$B$31) -> Envío gratis (obligatorio en Mercado Libre) | M13: =Parámetros!$B$32 -> No acepto | N13: =Parámetros!$B$33 -> Sin garantía | O13: MLM39455417 | P13: Motrin | Q13: Janssen-Cilag de México | R13: Infantil | S13: Suspensión 2 g/100 ml | T13: Suspensión oral | U13: 120 | V13: ml | W13: 1 | X13: Ibuprofeno | Y13: 20 mg/ml (2 g/100 ml) | Z13: Oral | AA13: Niños de 2 a 12 años | AC13: Frutas | AD13: Niños | AF13: 630M98 SSA VI | AG13: Formato de venta: Caja con frasco; Sin alcohol: Sí; Incluye vaso dosificador y pipeta dosificadora: Sí | AH13: https://raw.githubusercontent.com/zublimemx/marketplaces-product-images/main/products/7501109902866/images/7501109902866_1.jpg | AI13: https://raw.githubusercontent.com/zublimemx/marketplaces-product-images/main/products/7501109902866/images/7501109902866_2.jpg | AJ13: https://raw.githubusercontent.com/zublimemx/marketplaces-product-images/main/products/7501109902866/images/7501109902866_3.jpg | AK13: https://raw.githubusercontent.com/zublimemx/marketplaces-product-images/main/products/7501109902866/images/7501109902866_4.jpg | AN13: Farma | AO13: MOTRIN INF SUSP 20MG 1ML FEBRERO 28 30 | AP13: Verificado
A14: 7506425645749 | B14: 7506425645749 | C14: Pañales KleenBebé Suavelastic Etapa 7 XXJumbo 40 Piezas | D14: MLM178488 | E14: Bebés > Higiene y Cuidado del Bebé > Pañales > Desechables | F14: =Precios!R14 -> 493 | G14: 263 | H14: =Parámetros!$B$28 -> Nuevo | I14: =Parámetros!$B$29 -> Clásica | J14: Descripción: Los pañales KleenBebé Suavelastic Max Etapa 7 (Extra Extra Jumbo), de Kimberly-Clark, están pensados para mantener seco al bebé por mucho más tiempo. Combinan tecnología Blockgel de alta absorción, ajuste con cuatro puntos de sujeción y una fórmula suave con ingredientes como manzanilla, aloe vera y vitamina E. Versión unisex para bebés de de 16 a 24 kg. Características: - Maxi sequedad: tecnología Blockgel y centro absorbente de alto desempeño para mantener seco al bebé por más tiempo. - Maxi ajuste: cuatro puntos de sujeción que ayudan a que el pañal no se caiga ni se deforme, con orejas elásticas ajustables y barreras laterales suaves. - Maxi cuidado: fórmula Vitta E Plus con vitamina E, aloe vera y manzanilla, y óxido de zinc que ayuda a prevenir la irritación. - Bolsillo trasero que ayuda a evitar fugas cuando el bebé está acostado. - Dermatológicamente certificados. Modo de uso: Abra el pañal y colóquelo debajo del bebé, lleve la parte delantera hacia arriba y sujete las cintas a la altura de la cintura, sin apretar en exceso. Cámbielo con frecuencia, en cuanto esté húmedo o sucio. Presentación: Paquete con 40 pañales desechables Etapa 7 (Extra Extra Jumbo). Advertencias: Deseche el pañal usado en la basura, no en el inodoro. Mantenga el empaque plástico fuera del alcance de los niños. Verifique que la etapa corresponda al peso de su bebé. | K14: =Parámetros!$B$30 -> Mercado Envíos | L14: =IF(F14>=Parámetros!$B$7,"Envío gratis (obligatorio en Mercado Libre)",Parámetros!$B$31) -> Envío gratis (obligatorio en Mercado Libre) | M14: =Parámetros!$B$32 -> No acepto | N14: =Parámetros!$B$33 -> Sin garantía | O14: MLM23011505 | P14: KleenBebé | Q14: Kimberly-Clark de México | R14: Suavelastic | S14: Etapa 7 Extra Extra Jumbo | T14: Pañales desechables | U14: 40 | V14: piezas | W14: 40 | AA14: Etapa 7 | AB14: Extra Extra Jumbo | AD14: Unisex | AG14: Peso del bebé: 16 a 24 kg; Con óxido de zinc: Sí; Formato de venta: Paquete | AH14: https://raw.githubusercontent.com/zublimemx/marketplaces-product-images/main/products/7506425645749/images/7506425645749_2.jpg | AI14: https://raw.githubusercontent.com/zublimemx/marketplaces-product-images/main/products/7506425645749/images/7506425645749_5.jpg | AN14: Mark | AO14: SUAVE XJBO E7 C40 | AP14: Verificado
A15: 7501943441767 | B15: 7501943441767 | C15: Pañales Huggies Supreme Unisex Etapa 4 36 Piezas | D15: MLM178488 | E15: Bebés > Higiene y Cuidado del Bebé > Pañales > Desechables | F15: =Precios!R15 -> 422 | G15: 680 | H15: =Parámetros!$B$28 -> Nuevo | I15: =Parámetros!$B$29 -> Clásica | J15: Descripción: Los pañales Huggies Supreme Etapa 4, de Kimberly-Clark, están diseñados para proteger la delicada piel del bebé con materiales de superior suavidad. Es la línea Huggies que se presenta como única clínica y dermatológicamente probada, con certificación Dermatest de cinco estrellas. Versión unisex para bebés de 9 a 12 kg. Características: - Clínica y dermatológicamente probados, con certificación Dermatest de 5 estrellas. - Materiales de superior suavidad que ayudan a evitar la irritación. - Manejo de la humedad que ayuda a mantener la piel fresca y sana. - Cintas ajustables para un ajuste cómodo y seguro que permite libertad de movimiento. - Diseños exclusivos en los pañales. - Unisex: para niños y niñas. Modo de uso: Abra el pañal y colóquelo debajo del bebé, lleve la parte delantera hacia arriba y sujete las cintas a la altura de la cintura, sin apretar en exceso. Cámbielo con frecuencia, en cuanto esté húmedo o sucio. Presentación: Paquete con 36 pañales desechables Etapa 4. Advertencias: Deseche el pañal usado en la basura, no en el inodoro. Mantenga el empaque plástico fuera del alcance de los niños. Verifique que la etapa corresponda al peso de su bebé. | K15: =Parámetros!$B$30 -> Mercado Envíos | L15: =IF(F15>=Parámetros!$B$7,"Envío gratis (obligatorio en Mercado Libre)",Parámetros!$B$31) -> Envío gratis (obligatorio en Mercado Libre) | M15: =Parámetros!$B$32 -> No acepto | N15: =Parámetros!$B$33 -> Sin garantía | O15: MLM17379816 | P15: Huggies | Q15: Kimberly-Clark de México | R15: Supreme | S15: Etapa 4 | T15: Pañales desechables | U15: 36 | V15: piezas | W15: 36 | AA15: Etapa 4 | AB15: Etapa 4 | AD15: Unisex | AG15: Peso del bebé: 9 a 12 kg; Dermatest 5 estrellas: Sí; Formato de venta: Paquete | AH15: https://raw.githubusercontent.com/zublimemx/marketplaces-product-images/main/products/7501943441767/images/7501943441767_1.jpg | AI15: https://raw.githubusercontent.com/zublimemx/marketplaces-product-images/main/products/7501943441767/images/7501943441767_2.jpg | AN15: Mark | AO15: HU SUP UNISEX E4 C/36 | AP15: Verificado
A16: 7501943444942 | B16: 7501943444942 | C16: Pañales KleenBebé Suavelastic Etapa 4 Grande 44 Piezas | D16: MLM178488 | E16: Bebés > Higiene y Cuidado del Bebé > Pañales > Desechables | F16: =Precios!R16 -> 275 | G16: 604 | H16: =Parámetros!$B$28 -> Nuevo | I16: =Parámetros!$B$29 -> Clásica | J16: Descripción: Los pañales KleenBebé Suavelastic Max Etapa 4 (Grande), de Kimberly-Clark, están pensados para mantener seco al bebé por mucho más tiempo. Combinan tecnología Blockgel de alta absorción, ajuste con cuatro puntos de sujeción y una fórmula suave con ingredientes como manzanilla, aloe vera y vitamina E. Versión unisex para bebés de de 9 a 12 kg. Características: - Maxi sequedad: tecnología Blockgel y centro absorbente de alto desempeño para mantener seco al bebé por más tiempo. - Maxi ajuste: cuatro puntos de sujeción que ayudan a que el pañal no se caiga ni se deforme, con orejas elásticas ajustables y barreras laterales suaves. - Maxi cuidado: fórmula Vitta E Plus con vitamina E, aloe vera y manzanilla, y óxido de zinc que ayuda a prevenir la irritación. - Bolsillo trasero que ayuda a evitar fugas cuando el bebé está acostado. - Dermatológicamente certificados. Modo de uso: Abra el pañal y colóquelo debajo del bebé, lleve la parte delantera hacia arriba y sujete las cintas a la altura de la cintura, sin apretar en exceso. Cámbielo con frecuencia, en cuanto esté húmedo o sucio. Presentación: Paquete con 44 pañales desechables Etapa 4 (Grande). Advertencias: Deseche el pañal usado en la basura, no en el inodoro. Mantenga el empaque plástico fuera del alcance de los niños. Verifique que la etapa corresponda al peso de su bebé. | K16: =Parámetros!$B$30 -> Mercado Envíos | L16: =IF(F16>=Parámetros!$B$7,"Envío gratis (obligatorio en Mercado Libre)",Parámetros!$B$31) -> A cargo del comprador | M16: =Parámetros!$B$32 -> No acepto | N16: =Parámetros!$B$33 -> Sin garantía | O16: MLM42012939 | P16: KleenBebé | Q16: Kimberly-Clark de México | R16: Suavelastic | S16: Max Etapa 4 Grande | T16: Pañales desechables | U16: 44 | V16: piezas | W16: 44 | AA16: Etapa 4 | AB16: Grande | AD16: Unisex | AG16: Peso del bebé: 9 a 12 kg; Con óxido de zinc: Sí; Formato de venta: Paquete | AH16: https://raw.githubusercontent.com/zublimemx/marketplaces-product-images/main/products/7501943444942/images/7501943444942_2.jpg | AI16: https://raw.githubusercontent.com/zublimemx/marketplaces-product-images/main/products/7501943444942/images/7501943444942_5.jpg | AN16: Mark | AO16: SUAVE GDE E4 C/44 | AP16: Verificado
A17: 7501943447615 | B17: 7501943447615 | C17: Pañales KleenBebé Suavelastic Etapa 6 Extra Jumbo 40 Piezas | D17: MLM178488 | E17: Bebés > Higiene y Cuidado del Bebé > Pañales > Desechables | F17: =Precios!R17 -> 407 | G17: 610 | H17: =Parámetros!$B$28 -> Nuevo | I17: =Parámetros!$B$29 -> Clásica | J17: Descripción: Los pañales KleenBebé Suavelastic Max Etapa 6 (Extra Jumbo), de Kimberly-Clark, están pensados para mantener seco al bebé por mucho más tiempo. Combinan tecnología Blockgel de alta absorción, ajuste con cuatro puntos de sujeción y una fórmula suave con ingredientes como manzanilla, aloe vera y vitamina E. Versión unisex para bebés de de 13.5 a 17 kg. Características: - Maxi sequedad: tecnología Blockgel y centro absorbente de alto desempeño para mantener seco al bebé por más tiempo. - Maxi ajuste: cuatro puntos de sujeción que ayudan a que el pañal no se caiga ni se deforme, con orejas elásticas ajustables y barreras laterales suaves. - Maxi cuidado: fórmula Vitta E Plus con vitamina E, aloe vera y manzanilla, y óxido de zinc que ayuda a prevenir la irritación. - Bolsillo trasero que ayuda a evitar fugas cuando el bebé está acostado. - Dermatológicamente certificados. Modo de uso: Abra el pañal y colóquelo debajo del bebé, lleve la parte delantera hacia arriba y sujete las cintas a la altura de la cintura, sin apretar en exceso. Cámbielo con frecuencia, en cuanto esté húmedo o sucio. Presentación: Paquete con 40 pañales desechables Etapa 6 (Extra Jumbo). Advertencias: Deseche el pañal usado en la basura, no en el inodoro. Mantenga el empaque plástico fuera del alcance de los niños. Verifique que la etapa corresponda al peso de su bebé. | K17: =Parámetros!$B$30 -> Mercado Envíos | L17: =IF(F17>=Parámetros!$B$7,"Envío gratis (obligatorio en Mercado Libre)",Parámetros!$B$31) -> Envío gratis (obligatorio en Mercado Libre) | M17: =Parámetros!$B$32 -> No acepto | N17: =Parámetros!$B$33 -> Sin garantía | O17: MLM18976308 | P17: KleenBebé | Q17: Kimberly-Clark de México | R17: Suavelastic | S17: Max Etapa 6 Extra Jumbo | T17: Pañales desechables | U17: 40 | V17: piezas | W17: 40 | AA17: Etapa 6 | AB17: Extra Jumbo | AD17: Unisex | AG17: Peso del bebé: 13.5 a 17 kg; Con óxido de zinc: Sí; Formato de venta: Paquete | AH17: https://raw.githubusercontent.com/zublimemx/marketplaces-product-images/main/products/7501943447615/images/7501943447615_1.jpg | AI17: https://raw.githubusercontent.com/zublimemx/marketplaces-product-images/main/products/7501943447615/images/7501943447615_3.jpg | AN17: Mark | AO17: SUAVE EX JUM E6C/40 | AP17: Verificado
A18: 7501123013340 | B18: 7501123013340 | C18: Bedoyecta Complejo B Ácido Fólico Vitamina C 30 Cápsulas | D18: MLM438195 | E18: Salud y Equipamiento Médico > Suplementos Alimenticios | F18: =Precios!R18 -> 271.46 | G18: 2942 | H18: =Parámetros!$B$28 -> Nuevo | I18: =Parámetros!$B$29 -> Clásica | J18: Descripción: Bedoyecta Cápsulas, de Laboratorios Grossman, es un multivitamínico en cápsulas de gelatina blanda que reúne vitaminas del complejo B, ácido fólico, vitamina C y rutina. La presentación en gelatina blanda está pensada para una mejor absorción. Beneficios: - Ayuda a obtener la energía necesaria para las actividades del día y un buen rendimiento. - Cubre deficiencias de vitaminas del complejo B, ácido fólico y vitamina C. - Según su ficha, se utiliza en la prevención y el tratamiento de las deficiencias de las vitaminas que contiene, incluso en situaciones de mayor requerimiento como diabetes, alcoholismo o actividad física intensa. - Se indica también como apoyo en neuropatías nutricionales, alcohólicas y diabéticas, dolor de espalda, ciática y calambres musculares. Composición: Vitamina B1 (tiamina), vitamina B2 (riboflavina), vitamina B6 (piridoxina), vitamina B12 (cianocobalamina), ácido fólico, vitamina C (ácido ascórbico) y rutina. Las cantidades por cápsula se indican en la etiqueta del producto. Modo de uso: Vía oral. Tome las cápsulas según lo indicado en el empaque o por su médico. Presentación: Caja con 30 cápsulas de gelatina blanda. Advertencias: No exceda la dosis indicada. Si está embarazada, en lactancia o toma otros multivitamínicos o medicamentos, consulte a su médico antes de usarlo. Lea las instrucciones del empaque. Consulte a su médico. No se deje al alcance de los niños. | K18: =Parámetros!$B$30 -> Mercado Envíos | L18: =IF(F18>=Parámetros!$B$7,"Envío gratis (obligatorio en Mercado Libre)",Parámetros!$B$31) -> A cargo del comprador | M18: =Parámetros!$B$32 -> No acepto | N18: =Parámetros!$B$33 -> Sin garantía | O18: MLM45284329 | P18: Bedoyecta | Q18: Laboratorios Grossman | R18: Cápsulas | S18: Complejo B, ácido fólico, vitamina C y rutina | T18: Cápsulas de gelatina blanda | U18: 30 | V18: cápsulas | W18: 30 | X18: Complejo B, ácido fólico, vitamina C y rutina | Z18: Oral | AA18: Adultos | AG18: Tipo de suplemento: Multivitamínico; Formato de venta: Caja | AH18: https://raw.githubusercontent.com/zublimemx/marketplaces-product-images/main/products/7501123013340/images/7501123013340_1.jpg | AI18: https://raw.githubusercontent.com/zublimemx/marketplaces-product-images/main/products/7501123013340/images/7501123013340_2.jpg | AJ18: https://raw.githubusercontent.com/zublimemx/marketplaces-product-images/main/products/7501123013340/images/7501123013340_3.jpg | AN18: Farma | AO18: BEDOYECTA CAPS C 30 | AP18: Verificado
A19: 008400009418 | B19: 008400009418 | C19: Ribotripsin 18 mg 30 Tabletas | D19: MLM455222 | E19: Salud y Equipamiento Médico > Cuidado de la Salud > Farmacia > Medicamentos de Venta Libre > Antiinflamatorios | F19: =Precios!R19 -> 576.33 | G19: 1094 | H19: =Parámetros!$B$28 -> Nuevo | I19: =Parámetros!$B$29 -> Clásica | J19: Descripción: Ribotripsin es un medicamento de Laboratorios Grin en tabletas con capa entérica. Combina las enzimas proteolíticas tripsina y quimotripsina, que ayudan a acelerar la reparación de los tejidos. Beneficios: - Según su ficha, alivia el edema inflamatorio. - Favorece la reabsorción de la sangre extravasada (moretones) y de los exudados en contusiones leves. - Reduce el dolor en procesos inflamatorios postraumáticos. - Su capa entérica protege las tabletas de la acidez del estómago. Composición: Cada tableta contiene 18 mg de enzimas, equivalentes a tripsina 45,000 U USP y quimotripsina 9,000 U USP, con excipientes cbp. Modo de uso: Vía oral. La dosis habitual de referencia de la ficha es de dos tabletas cada 8 horas; la dosis y la duración del tratamiento deben ser indicadas por el médico. Presentación: Caja con 30 tabletas con capa entérica. Conservar a temperatura ambiente no mayor a 30 grados centígrados. Advertencias: No debe usarse en caso de hipersensibilidad a los componentes, pancreatitis aguda, síndromes hemorrágicos, insuficiencia hepática grave, insuficiencia cardíaca congestiva, hipoprotrombinemia ni antes de una cirugía próxima. No se recomienda su uso simultáneo con anticoagulantes; precaución en pacientes con úlcera gástrica. No lo consuma con bebidas alcohólicas. No se ha establecido su seguridad durante el embarazo y la lactancia. Puede causar molestias gastrointestinales leves, erupción o comezón. Lea las instrucciones del empaque. Consulte a su médico. No se deje al alcance de los niños. | K19: =Parámetros!$B$30 -> Mercado Envíos | L19: =IF(F19>=Parámetros!$B$7,"Envío gratis (obligatorio en Mercado Libre)",Parámetros!$B$31) -> Envío gratis (obligatorio en Mercado Libre) | M19: =Parámetros!$B$32 -> No acepto | N19: =Parámetros!$B$33 -> Sin garantía | O19: MLM39474731 | P19: Ribotripsin | Q19: Laboratorios Grin | S19: 18 mg | T19: Tabletas con capa entérica | U19: 30 | V19: tabletas | W19: 30 | X19: Tripsina y quimotripsina | Y19: 18 mg (45,000 U USP / 9,000 U USP) | Z19: Oral | AA19: Adultos | AF19: 65517 SSA IV | AG19: Formato de venta: Caja | AH19: https://raw.githubusercontent.com/zublimemx/marketplaces-product-images/main/products/008400009418/images/008400009418_1.jpg | AN19: Farma | AO19: RIBOTRIPSIN 18MG C30TAB | AP19: Verificado
A20: 7590002012468 | B20: 7590002012468 | C20: Vick VapoRub Ungüento Tópico 50 g | D20: MLM194695 | E20: Salud y Equipamiento Médico > Cuidado de la Salud > Farmacia > Medicamentos de Venta Libre > Antigripales | F20: =Precios!R20 -> 158.07 | G20: 241 | H20: =Parámetros!$B$28 -> Nuevo | I20: =Parámetros!$B$29 -> Clásica | J20: Descripción: Vick VapoRub es un ungüento tópico de Procter & Gamble elaborado con alcanfor, mentol y aceite de eucalipto en una base de petrolato. Se aplica sobre el pecho y el cuello para ayudar a aliviar la congestión nasal de los resfriados. Beneficios: - Ayuda a aliviar la congestión nasal para respirar con mayor facilidad y descansar mejor. - Se utiliza para el alivio temporal de la tos asociada al resfriado. - Puede aplicarse en la zona afectada para aliviar dolores musculares leves. - Aroma característico a mentol y eucalipto. Composición: Ingredientes activos: alcanfor, mentol y aceite de eucalipto. Excipientes, entre ellos petrolato, aceite de trementina, aceite de nuez moscada, aceite de hoja de cedro y timol. Modo de uso: Uso externo. Aplique una capa gruesa sobre el pecho y el cuello y frote hasta que se absorba; puede usarse por la mañana y por la noche. Para dolores musculares, frote en la zona afectada hasta cuatro veces al día. En niños mayores de 2 años, úselo bajo la supervisión de un adulto. Presentación: Tarro con 50 g de ungüento. Advertencias: No debe usarse en caso de hipersensibilidad a los componentes ni en menores de 2 años (contiene alcanfor). Evite el contacto con los ojos, no lo ingiera, no lo aplique en heridas ni en piel dañada, no lo introduzca en la nariz y no lo caliente directamente ni en horno de microondas por riesgo de quemaduras. Suspenda su uso si aparece irritación. Si presenta fiebre o los síntomas persisten por más de 3 días, consulte a su médico. Lea las instrucciones del empaque. Consulte a su médico. No se deje al alcance de los niños. | K20: =Parámetros!$B$30 -> Mercado Envíos | L20: =IF(F20>=Parámetros!$B$7,"Envío gratis (obligatorio en Mercado Libre)",Parámetros!$B$31) -> A cargo del comprador | M20: =Parámetros!$B$32 -> No acepto | N20: =Parámetros!$B$33 -> Sin garantía | O20: MLM45287887 | P20: Vick | Q20: Procter & Gamble | R20: VapoRub | S20: Ungüento tópico | T20: Ungüento | U20: 50 | V20: g | W20: 1 | X20: Alcanfor, mentol y aceite de eucalipto | Z20: Tópica | AA20: Niños mayores de 2 años y adultos | AC20: Mentol y eucalipto | AD20: Unisex | AG20: Formato de venta: Unidad; Envase: Tarro | AH20: https://raw.githubusercontent.com/zublimemx/marketplaces-product-images/main/products/7590002012468/images/7590002012468_1.jpg | AI20: https://raw.githubusercontent.com/zublimemx/marketplaces-product-images/main/products/7590002012468/images/7590002012468_3.jpg | AN20: Farma | AO20: VAPORUB 50GR TARRO 96 | AP20: Verificado
A21: 7501298217659 | B21: 7501298217659 | C21: Dolo-Neurobión DC Solución Inyectable 3 Jeringas 3 ml | D21: MLM457822 | E21: Salud y Equipamiento Médico > Cuidado de la Salud > Farmacia > Medicamentos de Venta Libre > Musculoarticulares Venta Libre | F21: =Precios!R21 -> 718.06 | G21: 1012 | H21: =Parámetros!$B$28 -> Nuevo | I21: =Parámetros!$B$29 -> Clásica | J21: Descripción: Dolo-Neurobión DC, de Merck, es una solución inyectable en jeringa prellenada de doble cámara de 3 ml. Combina el antiinflamatorio diclofenaco sódico con las vitaminas B1, B6 y B12 y el anestésico local lidocaína; las dos cámaras se mezclan justo antes de la aplicación. Beneficios: - Según su ficha, se utiliza para el alivio del dolor y la inflamación en lumbalgias, cervicalgias, braquialgias y radiculitis. - Se indica en neuropatías periféricas de diversas causas, como la neuropatía diabética. - Presentación de doble cámara que separa los componentes hasta el momento de su uso. Composición: Contenido de cada jeringa: - Diclofenaco sódico 75 mg - Vitamina B12 (cianocobalamina) 1 mg - Vitamina B1 (tiamina) 100 mg - Vitamina B6 (piridoxina) 100 mg - Lidocaína (clorhidrato) 20 mg Modo de uso: Vía intramuscular, aplicada por personal de salud. Antes de la aplicación se mezclan las soluciones de las dos cámaras. La dosis indicada en la ficha es una jeringa prellenada una vez al día; la duración del tratamiento debe ser determinada por el médico. Presentación: Caja con 3 jeringas prellenadas de doble cámara de 3 ml y agujas desechables. Advertencias: No debe usarse en caso de hipersensibilidad a los componentes, úlcera péptica, sensibilidad a la aspirina o a otros antiinflamatorios, trastornos de la sangre ni insuficiencia hepática. No se administre durante el embarazo ni la lactancia ni a menores de 12 años. Precaución en insuficiencia renal, hipertensión no controlada y tratamiento con levodopa. Puede causar náusea, vómito, mareo, dolor de cabeza y, rara vez, hemorragia gastroduodenal. Lea las instrucciones del empaque. Consulte a su médico. No se deje al alcance de los niños. | K21: =Parámetros!$B$30 -> Mercado Envíos | L21: =IF(F21>=Parámetros!$B$7,"Envío gratis (obligatorio en Mercado Libre)",Parámetros!$B$31) -> Envío gratis (obligatorio en Mercado Libre) | M21: =Parámetros!$B$32 -> No acepto | N21: =Parámetros!$B$33 -> Sin garantía | O21: MLM52121009 | P21: Dolo-Neurobión | Q21: Merck | R21: DC | S21: Doble cámara | T21: Solución inyectable en jeringa prellenada de doble cámara | U21: 3 | V21: ml | W21: 3 | X21: Diclofenaco, lidocaína y vitaminas B1, B6 y B12 | Y21: Diclofenaco 75 mg, vitamina B1 100 mg, vitamina B6 100 mg, vitamina B12 1 mg, lidocaína 20 mg por jeringa | Z21: Intramuscular | AA21: Adultos | AF21: 79717 SSA | AG21: Incluye agujas desechables: Sí; Formato de venta: Caja | AH21: https://raw.githubusercontent.com/zublimemx/marketplaces-product-images/main/products/7501298217659/images/7501298217659_3.jpg | AI21: https://raw.githubusercontent.com/zublimemx/marketplaces-product-images/main/products/7501298217659/images/7501298217659_4.jpg | AN21: Farma | AO21: DOLO NEUROBION DC C3AMP | AP21: Verificado
